/Users/wamiqueansari/Documents/275_gash/project/Tracking
/Users/wamiqueansari/Documents/275_gash/project/Tracking/uploads/
saving /Users/wamiqueansari/Documents/275_gash/project/Tracking/uploads/tweet-bookmark-icon.png
/Users/wamiqueansari/Documents/275_gash/project/Tracking
/Users/wamiqueansari/Documents/275_gash/project/Tracking/uploads/
saving /Users/wamiqueansari/Documents/275_gash/project/Tracking/uploads/tweet-bookmark-icon.png
/Users/wamiqueansari/Documents/275_gash/project/Tracking
/Users/wamiqueansari/Documents/275_gash/project/Tracking/uploads/
saving /Users/wamiqueansari/Documents/275_gash/project/Tracking/uploads/tweet-bookmark-icon.png
/Users/wamiqueansari/Documents/275_gash/project/Tracking
/Users/wamiqueansari/Documents/275_gash/project/Tracking/uploads/
saving /Users/wamiqueansari/Documents/275_gash/project/Tracking/uploads/tweet-bookmark-icon.png
/Users/wamiqueansari/Documents/275_gash/project/Tracking
/Users/wamiqueansari/Documents/275_gash/project/Tracking/uploads/
saving /Users/wamiqueansari/Documents/275_gash/project/Tracking/uploads/tweet-bookmark-icon.png
/Users/wamiqueansari/Documents/275_gash/project/Tracking
/Users/wamiqueansari/Documents/275_gash/project/Tracking/uploads/
saving /Users/wamiqueansari/Documents/275_gash/project/Tracking/uploads/tweet-bookmark-icon.png
C:\Users\Admin\python\Tracking
Exception on / [GET]
Traceback (most recent call last):
  File "C:\Users\Admin\Anaconda3\lib\site-packages\flask\app.py", line 2446, in wsgi_app
    response = self.full_dispatch_request()
  File "C:\Users\Admin\Anaconda3\lib\site-packages\flask\app.py", line 1951, in full_dispatch_request
    rv = self.handle_user_exception(e)
  File "C:\Users\Admin\Anaconda3\lib\site-packages\flask\app.py", line 1820, in handle_user_exception
    reraise(exc_type, exc_value, tb)
  File "C:\Users\Admin\Anaconda3\lib\site-packages\flask\_compat.py", line 39, in reraise
    raise value
  File "C:\Users\Admin\Anaconda3\lib\site-packages\flask\app.py", line 1949, in full_dispatch_request
    rv = self.dispatch_request()
  File "C:\Users\Admin\Anaconda3\lib\site-packages\flask\app.py", line 1935, in dispatch_request
    return self.view_functions[rule.endpoint](**req.view_args)
  File "server.py", line 38, in api_root
    performCaching("test me")
  File "server.py", line 43, in performCaching
    h = blake2b(digest_size=20)
NameError: name 'blake2b' is not defined
C:\Users\Admin\python\Tracking
Exception on / [GET]
Traceback (most recent call last):
  File "C:\Users\Admin\Anaconda3\lib\site-packages\flask\app.py", line 2446, in wsgi_app
    response = self.full_dispatch_request()
  File "C:\Users\Admin\Anaconda3\lib\site-packages\flask\app.py", line 1951, in full_dispatch_request
    rv = self.handle_user_exception(e)
  File "C:\Users\Admin\Anaconda3\lib\site-packages\flask\app.py", line 1820, in handle_user_exception
    reraise(exc_type, exc_value, tb)
  File "C:\Users\Admin\Anaconda3\lib\site-packages\flask\_compat.py", line 39, in reraise
    raise value
  File "C:\Users\Admin\Anaconda3\lib\site-packages\flask\app.py", line 1949, in full_dispatch_request
    rv = self.dispatch_request()
  File "C:\Users\Admin\Anaconda3\lib\site-packages\flask\app.py", line 1935, in dispatch_request
    return self.view_functions[rule.endpoint](**req.view_args)
  File "server.py", line 38, in api_root
    performCaching("test me")
  File "server.py", line 43, in performCaching
    h = blake2b(digest_size=20)
NameError: name 'blake2b' is not defined
C:\Users\Admin\python\Tracking
Exception on / [GET]
Traceback (most recent call last):
  File "C:\Users\Admin\Anaconda3\lib\site-packages\flask\app.py", line 2446, in wsgi_app
    response = self.full_dispatch_request()
  File "C:\Users\Admin\Anaconda3\lib\site-packages\flask\app.py", line 1952, in full_dispatch_request
    return self.finalize_request(rv)
  File "C:\Users\Admin\Anaconda3\lib\site-packages\flask\app.py", line 1967, in finalize_request
    response = self.make_response(rv)
  File "C:\Users\Admin\Anaconda3\lib\site-packages\flask\app.py", line 2097, in make_response
    "The view function did not return a valid response. The"
TypeError: The view function did not return a valid response. The function either returned None or ended without a return statement.
C:\Users\Admin\python\Tracking
C:\Users\Admin\python\Tracking
C:\Users\Admin\python\Tracking
C:\Users\Admin\python\Tracking
C:\Users\Admin\python\Tracking
C:\Users\Admin\python\Tracking
Exception on / [GET]
Traceback (most recent call last):
  File "C:\Users\Admin\Anaconda3\lib\site-packages\flask\app.py", line 2446, in wsgi_app
    response = self.full_dispatch_request()
  File "C:\Users\Admin\Anaconda3\lib\site-packages\flask\app.py", line 1951, in full_dispatch_request
    rv = self.handle_user_exception(e)
  File "C:\Users\Admin\Anaconda3\lib\site-packages\flask\app.py", line 1820, in handle_user_exception
    reraise(exc_type, exc_value, tb)
  File "C:\Users\Admin\Anaconda3\lib\site-packages\flask\_compat.py", line 39, in reraise
    raise value
  File "C:\Users\Admin\Anaconda3\lib\site-packages\flask\app.py", line 1949, in full_dispatch_request
    rv = self.dispatch_request()
  File "C:\Users\Admin\Anaconda3\lib\site-packages\flask\app.py", line 1935, in dispatch_request
    return self.view_functions[rule.endpoint](**req.view_args)
  File "server.py", line 41, in api_root
    print("----------------------------",request.args[fileName])
NameError: name 'fileName' is not defined
C:\Users\Admin\python\Tracking
C:\Users\Admin\python\Tracking
C:\Users\Admin\python\Tracking
C:\Users\Admin\python\Tracking
